Workbook

Sheet raw
A1: U_1
A2: 0.22916667 | B2: 0.2375 | C2: 0.24583333 | D2: 0.25416667 | E2: 0.26111111 | F2: 0.26805556 | G2: 0.27361111 | H2: 0.27916667 | I2: 0.28333333 | J2: 0.2875 | K2: 0.29166667 | L2: 0.29583333 | M2: 0.3 | N2: 0.30416667 | O2: 0.30833333 | P2: 0.31319444 | Q2: 0.31805556 | R2: 0.32291667 | S2: 0.32847222 | T2: 0.33402778
A3: 0.33958333 | B3: 0.34513889 | C3: 0.35555556 | D3: 0.36041667 | E3: 0.37152778 | F3: 0.38541667 | G3: 0.39930556 | H3: 0.41319444 | I3: 0.42708333 | J3: 0.44097222 | K3: 0.45486111 | L3: 0.46875 | M3: 0.48263889 | N3: 0.49652778 | O3: 0.51041667 | P3: 0.52430556 | Q3: 0.53819444 | R3: 0.55208333 | S3: 0.56597222 | T3: 0.57986111
A4: 0.59375 | B4: 0.60763889 | C4: 0.61458333 | D4: 0.62152778 | E4: 0.62847222 | F4: 0.63541667 | G4: 0.64236111 | H4: 0.64930556 | I4: 0.65625 | J4: 0.66319444 | K4: 0.66875 | L4: 0.67430556 | M4: 0.67986111 | N4: 0.68541667 | O4: 0.69097222 | P4: 0.69652778 | Q4: 0.70138889 | R4: 0.70694444 | S4: 0.7125 | T4: 0.71805556
A5: 0.72361111 | B5: 0.72916667 | C5: 0.73472222 | D5: 0.73958333 | E5: 0.74513889 | F5: 0.75 | G5: 0.75555556 | H5: 0.76111111 | I5: 0.76666667 | J5: 0.77291667 | K5: 0.77986111 | L5: 0.78680556 | M5: 0.79375 | N5: 0.80069444 | O5: 0.8125 | P5: 0.82638889 | Q5: 0.84027778 | R5: 0.85416667 | S5: 0.86805556 | T5: 0.88194444
A6: 0.89583333 | B6: 0.90972222 | C6: 0.92361111 | D6: 0.9375 | E6: 0.95138889 | F6: 0.96527778 | G6: 0.97916667
A8: U_2
A9: 0.22916667 | B9: 0.23958333 | C9: 0.25 | D9: 0.25555556 | E9: 0.26111111 | F9: 0.26666667 | G9: 0.27222222 | H9: 0.27777778 | I9: 0.28333333 | J9: 0.28888889 | K9: 0.29375 | L9: 0.3 | M9: 0.30555556 | N9: 0.31111111 | O9: 0.31597222 | P9: 0.32083333 | Q9: 0.32569444 | R9: 0.33055556 | S9: 0.33680556 | T9: 0.34305556
A10: 0.34930556 | B10: 0.35625 | C10: 0.36180556 | D10: 0.36805556 | E10: 0.37430556 | F10: 0.38055556 | G10: 0.38680556 | H10: 0.39305556 | I10: 0.39930556 | J10: 0.4125 | K10: 0.42638889 | L10: 0.44027778 | M10: 0.45416667 | N10: 0.46805556 | O10: 0.48194444 | P10: 0.49583333 | Q10: 0.50972222 | R10: 0.52361111 | S10: 0.5375 | T10: 0.55138889
A11: 0.56527778 | B11: 0.57916667 | C11: 0.59305556 | D11: 0.60625 | E11: 0.62013889 | F11: 0.63402778 | G11: 0.64791667 | H11: 0.66111111 | I11: 0.66736111 | J11: 0.67361111 | K11: 0.67916667 | L11: 0.68472222 | M11: 0.69027778 | N11: 0.69583333 | O11: 0.70138889 | P11: 0.70694444 | Q11: 0.71180556 | R11: 0.71597222 | S11: 0.72013889 | T11: 0.725
A12: 0.72986111 | B12: 0.73472222 | C12: 0.73888889 | D12: 0.74444444 | E12: 0.75 | F12: 0.75555556 | G12: 0.76111111 | H12: 0.76666667 | I12: 0.77291667 | J12: 0.77986111 | K12: 0.78680556 | L12: 0.79444444 | M12: 0.80208333 | N12: 0.81041667 | O12: 0.82083333 | P12: 0.83472222 | Q12: 0.84722222 | R12: 0.86111111 | S12: 0.875 | T12: 0.88888889
A13: 0.90277778 | B13: 0.91666667 | C13: 0.93055556 | D13: 0.9375 | E13: 0.95138889 | F13: 0.96527778 | G13: 0.97916667
A15: S_1
A16: 0.22916667 | B16: 0.24652778 | C16: 0.26388889 | D16: 0.27777778 | E16: 0.29166667 | F16: 0.30555556 | G16: 0.31944444 | H16: 0.33333333 | I16: 0.34444444 | J16: 0.36736111 | K16: 0.38888889 | L16: 0.41111111 | M16: 0.43333333 | N16: 0.45555556 | O16: 0.47777778 | P16: 0.5 | Q16: 0.52222222 | R16: 0.54444444 | S16: 0.56666667 | T16: 0.58888889
A17: 0.6125 | B17: 0.625 | C17: 0.6375 | D17: 0.65069444 | E17: 0.6625 | F17: 0.675 | G17: 0.68819444 | H17: 0.70833333 | I17: 0.72916667 | J17: 0.75 | K17: 0.77083333 | L17: 0.79166667 | M17: 0.8125 | N17: 0.83333333 | O17: 0.85416667 | P17: 0.875 | Q17: 0.89583333 | R17: 0.91666667 | S17: 0.9375 | T17: 0.95833333
A18: 0.97916667
A20: S_2
A21: 0.22916667 | B21: 0.24305556 | C21: 0.25694444 | D21: 0.27083333 | E21: 0.28472222 | F21: 0.29861111 | G21: 0.3125 | H21: 0.32638889 | I21: 0.34027778 | J21: 0.35347222 | K21: 0.36666667 | L21: 0.38194444 | M21: 0.40069444 | N21: 0.42291667 | O21: 0.44513889 | P21: 0.46736111 | Q21: 0.48958333 | R21: 0.51180556 | S21: 0.53402778 | T21: 0.55625
A22: 0.57847222 | B22: 0.60138889 | C22: 0.62430556 | D22: 0.64722222 | E22: 0.66319444 | F22: 0.67916667 | G22: 0.69583333 | H22: 0.7125 | I22: 0.72916667 | J22: 0.75 | K22: 0.77083333 | L22: 0.79166667 | M22: 0.8125 | N22: 0.83333333 | O22: 0.85416667 | P22: 0.875 | Q22: 0.89583333 | R22: 0.91666667 | S22: 0.9375 | T22: 0.95833333
A23: 0.97916667
A25: D_1
A26: 0.22916667 | B26: 0.25 | C26: 0.27083333 | D26: 0.29166667 | E26: 0.3125 | F26: 0.33333333 | G26: 0.35416667 | H26: 0.375 | I26: 0.39583333 | J26: 0.41666667 | K26: 0.4375 | L26: 0.45486111 | M26: 0.47222222 | N26: 0.48958333 | O26: 0.50694444 | P26: 0.52430556 | Q26: 0.54166667 | R26: 0.55902778 | S26: 0.57638889 | T26: 0.59375
A27: 0.61111111 | B27: 0.62847222 | C27: 0.64583333 | D27: 0.66319444 | E27: 0.68055556 | F27: 0.69791667 | G27: 0.71527778 | H27: 0.73263889 | I27: 0.75 | J27: 0.76736111 | K27: 0.78472222 | L27: 0.80208333 | M27: 0.81944444 | N27: 0.83680556 | O27: 0.85416667 | P27: 0.875 | Q27: 0.89583333 | R27: 0.91666667 | S27: 0.9375 | T27: 0.95833333
A28: 0.97916667
A30: D_2
A31: 0.22916667 | B31: 0.25 | C31: 0.27083333 | D31: 0.29166667 | E31: 0.3125 | F31: 0.33333333 | G31: 0.35416667 | H31: 0.375 | I31: 0.39583333 | J31: 0.41666667 | K31: 0.4375 | L31: 0.45486111 | M31: 0.47222222 | N31: 0.48958333 | O31: 0.50694444 | P31: 0.52430556 | Q31: 0.54166667 | R31: 0.55902778 | S31: 0.57638889 | T31: 0.59375
A32: 0.61111111 | B32: 0.62847222 | C32: 0.64583333 | D32: 0.66319444 | E32: 0.68055556 | F32: 0.69791667 | G32: 0.71527778 | H32: 0.73263889 | I32: 0.75 | J32: 0.76736111 | K32: 0.78472222 | L32: 0.80208333 | M32: 0.81944444 | N32: 0.83680556 | O32: 0.85416667 | P32: 0.875 | Q32: 0.89583333 | R32: 0.91666667 | S32: 0.9375 | T32: 0.95833333
A33: 0.97916667

Sheet long
A1: proto_service | B1: stop_name | C1: departure
A2: U_1 | B2: Terminal Barreiros | C2: {=TRANSPOSE(raw!$A$2:$T$2)} -> 0.22916667
A3: U_1 | B3: Terminal Barreiros | C3: 0.2375
A4: U_1 | B4: Terminal Barreiros | C4: 0.24583333
A5: U_1 | B5: Terminal Barreiros | C5: 0.25416667
A6: U_1 | B6: Terminal Barreiros | C6: 0.26111111
A7: U_1 | B7: Terminal Barreiros | C7: 0.26805556
A8: U_1 | B8: Terminal Barreiros | C8: 0.27361111
A9: U_1 | B9: Terminal Barreiros | C9: 0.27916667
A10: U_1 | B10: Terminal Barreiros | C10: 0.28333333
A11: U_1 | B11: Terminal Barreiros | C11: 0.2875
A12: U_1 | B12: Terminal Barreiros | C12: 0.29166667
A13: U_1 | B13: Terminal Barreiros | C13: 0.29583333
A14: U_1 | B14: Terminal Barreiros | C14: 0.3
... A21: U_1 | B21: Terminal Barreiros | C21: 0.33402778
A22: U_1 | B22: Terminal Barreiros | C22: {=TRANSPOSE(raw!$A$3:$T$3)} -> 0.33958333
A23: U_1 | B23: Terminal Barreiros | C23: 0.34513889
A24: U_1 | B24: Terminal Barreiros | C24: 0.35555556
A25: U_1 | B25: Terminal Barreiros | C25: 0.36041667
A26: U_1 | B26: Terminal Barreiros | C26: 0.37152778
A27: U_1 | B27: Terminal Barreiros | C27: 0.38541667
A28: U_1 | B28: Terminal Barreiros | C28: 0.39930556
A29: U_1 | B29: Terminal Barreiros | C29: 0.41319444
A30: U_1 | B30: Terminal Barreiros | C30: 0.42708333
A31: U_1 | B31: Terminal Barreiros | C31: 0.44097222
A32: U_1 | B32: Terminal Barreiros | C32: 0.45486111
A33: U_1 | B33: Terminal Barreiros | C33: 0.46875
A34: U_1 | B34: Terminal Barreiros | C34: 0.48263889
... A41: U_1 | B41: Terminal Barreiros | C41: 0.57986111
A42: U_1 | B42: Terminal Barreiros | C42: {=TRANSPOSE(raw!$A$4:$T$4)} -> 0.59375
A43: U_1 | B43: Terminal Barreiros | C43: 0.60763889
A44: U_1 | B44: Terminal Barreiros | C44: 0.61458333
A45: U_1 | B45: Terminal Barreiros | C45: 0.62152778
A46: U_1 | B46: Terminal Barreiros | C46: 0.62847222
A47: U_1 | B47: Terminal Barreiros | C47: 0.63541667
A48: U_1 | B48: Terminal Barreiros | C48: 0.64236111
A49: U_1 | B49: Terminal Barreiros | C49: 0.64930556
A50: U_1 | B50: Terminal Barreiros | C50: 0.65625
A51: U_1 | B51: Terminal Barreiros | C51: 0.66319444
A52: U_1 | B52: Terminal Barreiros | C52: 0.66875
...
